API is running on IP address:
192.168.2.166
[33m * Tip: There are .env or .flaskenv files present. Do "pip install python-dotenv" to use them.[0m
 * Serving Flask app "api" (lazy loading)
 * Environment: production
[31m   WARNING: This is a development server. Do not use it in a production deployment.[0m
[2m   Use a production WSGI server instead.[0m
 * Debug mode: off
 * Running on http://192.168.2.166:9090/ (Press CTRL+C to quit)
bash: src/restart_dt_container.sh: No such file or directory
[2021-12-09 13:53:39,230] ERROR in app: Exception on /restart_dt_container [GET]
Traceback (most recent call last):
  File "/usr/local/lib/python2.7/dist-packages/flask/app.py", line 2447, in wsgi_app
    response = self.full_dispatch_request()
  File "/usr/local/lib/python2.7/dist-packages/flask/app.py", line 1952, in full_dispatch_request
    rv = self.handle_user_exception(e)
  File "/usr/local/lib/python2.7/dist-packages/flask_cors/extension.py", line 165, in wrapped_function
    return cors_after_request(app.make_response(f(*args, **kwargs)))
  File "/usr/local/lib/python2.7/dist-packages/flask/app.py", line 1821, in handle_user_exception
    reraise(exc_type, exc_value, tb)
  File "/usr/local/lib/python2.7/dist-packages/flask/app.py", line 1950, in full_dispatch_request
    rv = self.dispatch_request()
  File "/usr/local/lib/python2.7/dist-packages/flask/app.py", line 1936, in dispatch_request
    return self.view_functions[rule.endpoint](**req.view_args)
  File "/usr/local/lib/python2.7/dist-packages/flask_cors/decorator.py", line 128, in wrapped_function
    resp = make_response(f(*args, **kwargs))
  File "./../../src/pyrest/api.py", line 126, in restart
    result_success = subprocess.check_output("bash src/restart_dt_container.sh", shell=True)
  File "/usr/lib/python2.7/subprocess.py", line 223, in check_output
    raise CalledProcessError(retcode, cmd, output=output)
CalledProcessError: Command 'bash src/restart_dt_container.sh' returned non-zero exit status 127
10.10.2.14 - - [09/Dec/2021 13:53:39] "[35m[1mGET /restart_dt_container HTTP/1.1[0m" 500 -
bash: src/restart_dt_container.sh: No such file or directory
[2021-12-09 13:58:56,581] ERROR in app: Exception on /restart_dt_container [GET]
Traceback (most recent call last):
  File "/usr/local/lib/python2.7/dist-packages/flask/app.py", line 2447, in wsgi_app
    response = self.full_dispatch_request()
  File "/usr/local/lib/python2.7/dist-packages/flask/app.py", line 1952, in full_dispatch_request
    rv = self.handle_user_exception(e)
  File "/usr/local/lib/python2.7/dist-packages/flask_cors/extension.py", line 165, in wrapped_function
    return cors_after_request(app.make_response(f(*args, **kwargs)))
  File "/usr/local/lib/python2.7/dist-packages/flask/app.py", line 1821, in handle_user_exception
    reraise(exc_type, exc_value, tb)
  File "/usr/local/lib/python2.7/dist-packages/flask/app.py", line 1950, in full_dispatch_request
    rv = self.dispatch_request()
  File "/usr/local/lib/python2.7/dist-packages/flask/app.py", line 1936, in dispatch_request
    return self.view_functions[rule.endpoint](**req.view_args)
  File "/usr/local/lib/python2.7/dist-packages/flask_cors/decorator.py", line 128, in wrapped_function
    resp = make_response(f(*args, **kwargs))
  File "./../../src/pyrest/api.py", line 126, in restart
    result_success = subprocess.check_output("bash src/restart_dt_container.sh", shell=True)
  File "/usr/lib/python2.7/subprocess.py", line 223, in check_output
    raise CalledProcessError(retcode, cmd, output=output)
CalledProcessError: Command 'bash src/restart_dt_container.sh' returned non-zero exit status 127
10.10.2.14 - - [09/Dec/2021 13:58:56] "[35m[1mGET /restart_dt_container HTTP/1.1[0m" 500 -
bash: src/restart_dt_container.sh: No such file or directory
[2021-12-09 14:00:43,485] ERROR in app: Exception on /restart_dt_container [GET]
Traceback (most recent call last):
  File "/usr/local/lib/python2.7/dist-packages/flask/app.py", line 2447, in wsgi_app
    response = self.full_dispatch_request()
  File "/usr/local/lib/python2.7/dist-packages/flask/app.py", line 1952, in full_dispatch_request
    rv = self.handle_user_exception(e)
  File "/usr/local/lib/python2.7/dist-packages/flask_cors/extension.py", line 165, in wrapped_function
    return cors_after_request(app.make_response(f(*args, **kwargs)))
  File "/usr/local/lib/python2.7/dist-packages/flask/app.py", line 1821, in handle_user_exception
    reraise(exc_type, exc_value, tb)
  File "/usr/local/lib/python2.7/dist-packages/flask/app.py", line 1950, in full_dispatch_request
    rv = self.dispatch_request()
  File "/usr/local/lib/python2.7/dist-packages/flask/app.py", line 1936, in dispatch_request
    return self.view_functions[rule.endpoint](**req.view_args)
  File "/usr/local/lib/python2.7/dist-packages/flask_cors/decorator.py", line 128, in wrapped_function
    resp = make_response(f(*args, **kwargs))
  File "./../../src/pyrest/api.py", line 126, in restart
    result_success = subprocess.check_output("bash src/restart_dt_container.sh", shell=True)
  File "/usr/lib/python2.7/subprocess.py", line 223, in check_output
    raise CalledProcessError(retcode, cmd, output=output)
CalledProcessError: Command 'bash src/restart_dt_container.sh' returned non-zero exit status 127
10.10.2.14 - - [09/Dec/2021 14:00:43] "[35m[1mGET /restart_dt_container HTTP/1.1[0m" 500 -
bash: src/restart_dt_container.sh: No such file or directory
[2021-12-09 14:07:43,021] ERROR in app: Exception on /restart_dt_container [GET]
Traceback (most recent call last):
  File "/usr/local/lib/python2.7/dist-packages/flask/app.py", line 2447, in wsgi_app
    response = self.full_dispatch_request()
  File "/usr/local/lib/python2.7/dist-packages/flask/app.py", line 1952, in full_dispatch_request
    rv = self.handle_user_exception(e)
  File "/usr/local/lib/python2.7/dist-packages/flask_cors/extension.py", line 165, in wrapped_function
    return cors_after_request(app.make_response(f(*args, **kwargs)))
  File "/usr/local/lib/python2.7/dist-packages/flask/app.py", line 1821, in handle_user_exception
    reraise(exc_type, exc_value, tb)
  File "/usr/local/lib/python2.7/dist-packages/flask/app.py", line 1950, in full_dispatch_request
    rv = self.dispatch_request()
  File "/usr/local/lib/python2.7/dist-packages/flask/app.py", line 1936, in dispatch_request
    return self.view_functions[rule.endpoint](**req.view_args)
  File "/usr/local/lib/python2.7/dist-packages/flask_cors/decorator.py", line 128, in wrapped_function
    resp = make_response(f(*args, **kwargs))
  File "./../../src/pyrest/api.py", line 126, in restart
    result_success = subprocess.check_output("bash src/restart_dt_container.sh", shell=True)
  File "/usr/lib/python2.7/subprocess.py", line 223, in check_output
    raise CalledProcessError(retcode, cmd, output=output)
CalledProcessError: Command 'bash src/restart_dt_container.sh' returned non-zero exit status 127
10.10.2.14 - - [09/Dec/2021 14:07:43] "[35m[1mGET /restart_dt_container HTTP/1.1[0m" 500 -
bash: src/restart_dt_container.sh: No such file or directory
[2021-12-09 14:09:07,586] ERROR in app: Exception on /restart_dt_container [GET]
Traceback (most recent call last):
  File "/usr/local/lib/python2.7/dist-packages/flask/app.py", line 2447, in wsgi_app
    response = self.full_dispatch_request()
  File "/usr/local/lib/python2.7/dist-packages/flask/app.py", line 1952, in full_dispatch_request
    rv = self.handle_user_exception(e)
  File "/usr/local/lib/python2.7/dist-packages/flask_cors/extension.py", line 165, in wrapped_function
    return cors_after_request(app.make_response(f(*args, **kwargs)))
  File "/usr/local/lib/python2.7/dist-packages/flask/app.py", line 1821, in handle_user_exception
    reraise(exc_type, exc_value, tb)
  File "/usr/local/lib/python2.7/dist-packages/flask/app.py", line 1950, in full_dispatch_request
    rv = self.dispatch_request()
  File "/usr/local/lib/python2.7/dist-packages/flask/app.py", line 1936, in dispatch_request
    return self.view_functions[rule.endpoint](**req.view_args)
  File "/usr/local/lib/python2.7/dist-packages/flask_cors/decorator.py", line 128, in wrapped_function
    resp = make_response(f(*args, **kwargs))
  File "./../../src/pyrest/api.py", line 126, in restart
    result_success = subprocess.check_output("bash src/restart_dt_container.sh", shell=True)
  File "/usr/lib/python2.7/subprocess.py", line 223, in check_output
    raise CalledProcessError(retcode, cmd, output=output)
CalledProcessError: Command 'bash src/restart_dt_container.sh' returned non-zero exit status 127
10.10.2.14 - - [09/Dec/2021 14:09:07] "[35m[1mGET /restart_dt_container HTTP/1.1[0m" 500 -
bash: src/restart_dt_container.sh: No such file or directory
[2021-12-09 14:20:43,474] ERROR in app: Exception on /restart_dt_container [GET]
Traceback (most recent call last):
  File "/usr/local/lib/python2.7/dist-packages/flask/app.py", line 2447, in wsgi_app
    response = self.full_dispatch_request()
  File "/usr/local/lib/python2.7/dist-packages/flask/app.py", line 1952, in full_dispatch_request
    rv = self.handle_user_exception(e)
  File "/usr/local/lib/python2.7/dist-packages/flask_cors/extension.py", line 165, in wrapped_function
    return cors_after_request(app.make_response(f(*args, **kwargs)))
  File "/usr/local/lib/python2.7/dist-packages/flask/app.py", line 1821, in handle_user_exception
    reraise(exc_type, exc_value, tb)
  File "/usr/local/lib/python2.7/dist-packages/flask/app.py", line 1950, in full_dispatch_request
    rv = self.dispatch_request()
  File "/usr/local/lib/python2.7/dist-packages/flask/app.py", line 1936, in dispatch_request
    return self.view_functions[rule.endpoint](**req.view_args)
  File "/usr/local/lib/python2.7/dist-packages/flask_cors/decorator.py", line 128, in wrapped_function
    resp = make_response(f(*args, **kwargs))
  File "./../../src/pyrest/api.py", line 126, in restart
    result_success = subprocess.check_output("bash src/restart_dt_container.sh", shell=True)
  File "/usr/lib/python2.7/subprocess.py", line 223, in check_output
    raise CalledProcessError(retcode, cmd, output=output)
CalledProcessError: Command 'bash src/restart_dt_container.sh' returned non-zero exit status 127
10.10.2.14 - - [09/Dec/2021 14:20:43] "[35m[1mGET /restart_dt_container HTTP/1.1[0m" 500 -
